2022-07-09 11:30:48.480134: E tensorflow/stream_executor/cuda/cuda_driver.cc:271] failed call to cuInit: CUDA_ERROR_NO_DEVICE: no CUDA-capable device is detected
2022-07-09 11:30:48.480193: I tensorflow/stream_executor/cuda/cuda_diagnostics.cc:169] retrieving CUDA diagnostic information for host: crc2
2022-07-09 11:30:48.480200: I tensorflow/stream_executor/cuda/cuda_diagnostics.cc:176] hostname: crc2
2022-07-09 11:30:48.480268: I tensorflow/stream_executor/cuda/cuda_diagnostics.cc:200] libcuda reported version is: 465.27.0
2022-07-09 11:30:48.480289: I tensorflow/stream_executor/cuda/cuda_diagnostics.cc:204] kernel reported version is: 465.27.0
2022-07-09 11:30:48.480295: I tensorflow/stream_executor/cuda/cuda_diagnostics.cc:310] kernel version seems to match DSO: 465.27.0
2022-07-09 11:30:48.480983: I tensorflow/core/platform/cpu_feature_guard.cc:142] This TensorFlow binary is optimized with oneAPI Deep Neural Network Library (oneDNN) to use the following CPU instructions in performance-critical operations:  AVX2 AVX512F FMA
To enable them in other operations, rebuild TensorFlow with the appropriate compiler flags.
2022-07-09 11:30:52.779602: I tensorflow/compiler/mlir/mlir_graph_optimization_pass.cc:185] None of the MLIR Optimization Passes are enabled (registered 2)
Traceback (most recent call last):
  File "/cr/users/filip/Trigger/test_new_framework.py", line 8, in <module>
    Classifier.train((Trainingset, Testingset), epochs = 1, verbose = 1)
  File "/cr/users/filip/Trigger/TriggerStudyBinaries/Classifier.py", line 87, in train
    self.model.fit(TrainingSet, validation_data = ValidationSet, epochs = epochs, verbose = verbosity)
  File "/cr/data01/hahn/envs/tfenv/lib/python3.8/site-packages/keras/engine/training.py", line 1184, in fit
    tmp_logs = self.train_function(iterator)
  File "/cr/data01/hahn/envs/tfenv/lib/python3.8/site-packages/keras/engine/training.py", line 853, in train_function
    return step_function(self, iterator)
  File "/cr/data01/hahn/envs/tfenv/lib/python3.8/site-packages/keras/engine/training.py", line 842, in step_function
    outputs = model.distribute_strategy.run(run_step, args=(data,))
  File "/cr/data01/hahn/envs/tfenv/lib/python3.8/site-packages/tensorflow/python/distribute/distribute_lib.py", line 1286, in run
    return self._extended.call_for_each_replica(fn, args=args, kwargs=kwargs)
  File "/cr/data01/hahn/envs/tfenv/lib/python3.8/site-packages/tensorflow/python/distribute/distribute_lib.py", line 2849, in call_for_each_replica
    return self._call_for_each_replica(fn, args, kwargs)
  File "/cr/data01/hahn/envs/tfenv/lib/python3.8/site-packages/tensorflow/python/distribute/distribute_lib.py", line 3632, in _call_for_each_replica
    return fn(*args, **kwargs)
  File "/cr/data01/hahn/envs/tfenv/lib/python3.8/site-packages/tensorflow/python/autograph/impl/api.py", line 597, in wrapper
    return func(*args, **kwargs)
  File "/cr/data01/hahn/envs/tfenv/lib/python3.8/site-packages/keras/engine/training.py", line 835, in run_step
    outputs = model.train_step(data)
  File "/cr/data01/hahn/envs/tfenv/lib/python3.8/site-packages/keras/engine/training.py", line 787, in train_step
    y_pred = self(x, training=True)
  File "/cr/data01/hahn/envs/tfenv/lib/python3.8/site-packages/keras/engine/base_layer.py", line 1020, in __call__
    input_spec.assert_input_compatibility(self.input_spec, inputs, self.name)
  File "/cr/data01/hahn/envs/tfenv/lib/python3.8/site-packages/keras/engine/input_spec.py", line 229, in assert_input_compatibility
    raise ValueError('Input ' + str(input_index) + ' of layer ' +
ValueError: Input 0 of layer sequential is incompatible with the layer: : expected min_ndim=4, found ndim=3. Full shape received: (2123, 3, 120)
2022-07-09 11:30:53.185580: W tensorflow/core/kernels/data/generator_dataset_op.cc:107] Error occurred when finalizing GeneratorDataset iterator: Failed precondition: Python interpreter state is not initialized. The process may be terminated.
	 [[{{node PyFunc}}]]
